<?xml version="1.0" encoding="utf-8"?>
<!-- This URDF was automatically created by SolidWorks to URDF Exporter! Originally created by Stephen Brawner (brawner@gmail.com) 
     Commit Version: 1.6.0-4-g7f85cfe  Build Version: 1.6.7995.38578
     For more information, please see http://wiki.ros.org/sw_urdf_exporter -->
<robot
  name="auto_robot">
  <link
    name="base_link">
    <inertial>
      <origin
        xyz="2.8395E-05 0.00044016 0.070761"
        rpy="0 0 0" />
      <mass
        value="3.4984" />
      <inertia
        ixx="0.020694"
        ixy="2.8459E-05"
        ixz="-8.6816E-11"
        iyy="0.033952"
        iyz="5.3228E-08"
        izz="0.053792" />
    </inertial>
    <visual>
      <origin
        xyz="0 0 0"
        rpy="0 0 0" />
      <geometry>
        <mesh
          filename="package://auto_robot/meshes/base_link.STL" />
      </geometry>
      <material
        name="">
        <color
          rgba="0.79216 0.81961 0.93333 1" />
      </material>
    </visual>
    <collision>
      <origin
        xyz="0 0 0"
        rpy="0 0 0" />
      <geometry>
        <mesh
          filename="package://auto_robot/meshes/base_link.STL" />
      </geometry>
    </collision>
  </link>
  <link
    name="lidar_link">
    <inertial>
      <origin
        xyz="-0.0001996 -6.3239E-06 -0.038065"
        rpy="0 0 0" />
      <mass
        value="0.14189" />
      <inertia
        ixx="4.1798E-05"
        ixy="-5.6088E-09"
        ixz="3.0531E-07"
        iyy="4.5077E-05"
        iyz="-4.385E-10"
        izz="6.88E-05" />
    </inertial>
    <visual>
      <origin
        xyz="0 0 0"
        rpy="0 0 0" />
      <geometry>
        <mesh
          filename="package://auto_robot/meshes/lidar_link.STL" />
      </geometry>
      <material
        name="">
        <color
          rgba="0.79216 0.81961 0.93333 1" />
      </material>
    </visual>
    <collision>
      <origin
        xyz="0 0 0"
        rpy="0 0 0" />
      <geometry>
        <mesh
          filename="package://auto_robot/meshes/lidar_link.STL" />
      </geometry>
    </collision>
  </link>
  <joint
    name="lidar_joint"
    type="fixed">
    <origin
      xyz="0.018849 0.0022859 0.2251"
      rpy="0 0 0" />
    <parent
      link="base_link" />
    <child
      link="lidar_link" />
    <axis
      xyz="0 0 0" />
  </joint>
  <link
    name="imu_link">
    <inertial>
      <origin
        xyz="3.4694E-18 1.0408E-17 -0.005"
        rpy="0 0 0" />
      <mass
        value="0.027" />
      <inertia
        ixx="4.7813E-06"
        ixy="-1.6047E-21"
        ixz="5.294E-23"
        iyy="8.325E-06"
        iyz="2.412E-23"
        izz="1.2656E-05" />
    </inertial>
    <visual>
      <origin
        xyz="0 0 0"
        rpy="0 0 0" />
      <geometry>
        <mesh
          filename="package://auto_robot/meshes/imu_link.STL" />
      </geometry>
      <material
        name="">
        <color
          rgba="0.79216 0.81961 0.93333 1" />
      </material>
    </visual>
    <collision>
      <origin
        xyz="0 0 0"
        rpy="0 0 0" />
      <geometry>
        <mesh
          filename="package://auto_robot/meshes/imu_link.STL" />
      </geometry>
    </collision>
  </link>
  <joint
    name="imu_joint"
    type="fixed">
    <origin
      xyz="0 0 0.013"
      rpy="0 0 0" />
    <parent
      link="base_link" />
    <child
      link="imu_link" />
    <axis
      xyz="0 0 0" />
  </joint>
  <link
    name="camera_link">
    <inertial>
      <origin
        xyz="-0.013293 0.0014082 -2.3277E-05"
        rpy="0 0 0" />
      <mass
        value="0.036474" />
      <inertia
        ixx="2.3404E-05"
        ixy="2.1067E-07"
        ixz="1.0154E-08"
        iyy="3.5065E-06"
        iyz="1.7436E-09"
        izz="2.3613E-05" />
    </inertial>
    <visual>
      <origin
        xyz="0 0 0"
        rpy="0 0 0" />
      <geometry>
        <mesh
          filename="package://auto_robot/meshes/camera_link.STL" />
      </geometry>
      <material
        name="">
        <color
          rgba="0.70196 0.70196 0.70196 1" />
      </material>
    </visual>
    <collision>
      <origin
        xyz="0 0 0"
        rpy="0 0 0" />
      <geometry>
        <mesh
          filename="package://auto_robot/meshes/camera_link.STL" />
      </geometry>
    </collision>
  </link>
  <joint
    name="camera_joint"
    type="fixed">
    <origin
      xyz="0.29146 0.0033941 0.15158"
      rpy="0 0 0" />
    <parent
      link="base_link" />
    <child
      link="camera_link" />
    <axis
      xyz="0 0 0" />
  </joint>
  <link
    name="fl_wheel_link">
    <inertial>
      <origin
        xyz="-0.0013062 -0.014419 3.2463E-05"
        rpy="0 0 0" />
      <mass
        value="0.21481" />
      <inertia
        ixx="0.00010361"
        ixy="4.5758E-08"
        ixz="-3.0352E-07"
        iyy="0.00018482"
        iyz="1.2751E-07"
        izz="0.00010389" />
    </inertial>
    <visual>
      <origin
        xyz="0 0 0"
        rpy="0 0 0" />
      <geometry>
        <mesh
          filename="package://auto_robot/meshes/fl_wheel_link.STL" />
      </geometry>
      <material
        name="">
        <color
          rgba="1 1 1 1" />
      </material>
    </visual>
    <collision>
      <origin
        xyz="0 0 0"
        rpy="0 0 0" />
      <geometry>
        <mesh
          filename="package://auto_robot/meshes/fl_wheel_link.STL" />
      </geometry>
    </collision>
  </link>
  <joint
    name="fl_wheel_joint"
    type="continuous">
    <origin
      xyz="0.1915 0.22265 0.03599"
      rpy="0 0 0" />
    <parent
      link="base_link" />
    <child
      link="fl_wheel_link" />
    <axis
      xyz="2.0172E-05 -1 0" />
  </joint>
  <link
    name="rl_wheel_link">
    <inertial>
      <origin
        xyz="0.0013104 -0.014182 4.4596E-05"
        rpy="0 0 0" />
      <mass
        value="0.21481" />
      <inertia
        ixx="0.0001036"
        ixy="4.7955E-08"
        ixz="2.9864E-07"
        iyy="0.00018482"
        iyz="-1.2671E-07"
        izz="0.0001039" />
    </inertial>
    <visual>
      <origin
        xyz="0 0 0"
        rpy="0 0 0" />
      <geometry>
        <mesh
          filename="package://auto_robot/meshes/rl_wheel_link.STL" />
      </geometry>
      <material
        name="">
        <color
          rgba="1 1 1 1" />
      </material>
    </visual>
    <collision>
      <origin
        xyz="0 0 0"
        rpy="0 0 0" />
      <geometry>
        <mesh
          filename="package://auto_robot/meshes/rl_wheel_link.STL" />
      </geometry>
    </collision>
  </link>
  <joint
    name="rl_wheel_joint"
    type="continuous">
    <origin
      xyz="-0.1915 0.22464 0.036"
      rpy="0 0 0" />
    <parent
      link="base_link" />
    <child
      link="rl_wheel_link" />
    <axis
      xyz="0 1 0" />
  </joint>
  <link
    name="fr_wheel_link">
    <inertial>
      <origin
        xyz="0.00044882 0.014419 0.0012271"
        rpy="0 0 0" />
      <mass
        value="0.21481" />
      <inertia
        ixx="0.00010364"
        ixy="1.3487E-07"
        ixz="-3.1642E-07"
        iyy="0.00018482"
        iyz="-4.4754E-09"
        izz="0.00010386" />
    </inertial>
    <visual>
      <origin
        xyz="0 0 0"
        rpy="0 0 0" />
      <geometry>
        <mesh
          filename="package://auto_robot/meshes/fr_wheel_link.STL" />
      </geometry>
      <material
        name="">
        <color
          rgba="1 1 1 1" />
      </material>
    </visual>
    <collision>
      <origin
        xyz="0 0 0"
        rpy="0 0 0" />
      <geometry>
        <mesh
          filename="package://auto_robot/meshes/fr_wheel_link.STL" />
      </geometry>
    </collision>
  </link>
  <joint
    name="fr_wheel_joint"
    type="continuous">
    <origin
      xyz="0.19151 -0.22065 0.036001"
      rpy="0 0 0" />
    <parent
      link="base_link" />
    <child
      link="fr_wheel_link" />
    <axis
      xyz="0 1 0" />
  </joint>
  <link
    name="rr_wheel_link">
    <inertial>
      <origin
        xyz="0 0 0"
        rpy="0 0 0" />
      <mass
        value="0" />
      <inertia
        ixx="0"
        ixy="0"
        ixz="0"
        iyy="0"
        iyz="0"
        izz="0" />
    </inertial>
    <visual>
      <origin
        xyz="0 0 0"
        rpy="0 0 0" />
      <geometry>
        <mesh
          filename="package://auto_robot/meshes/rr_wheel_link.STL" />
      </geometry>
      <material
        name="">
        <color
          rgba="1 1 1 1" />
      </material>
    </visual>
    <collision>
      <origin
        xyz="0 0 0"
        rpy="0 0 0" />
      <geometry>
        <mesh
          filename="package://auto_robot/meshes/rr_wheel_link.STL" />
      </geometry>
    </collision>
  </link>
  <joint
    name="rr_wheel_joint"
    type="continuous">
    <origin
      xyz="-0.1915 -0.22264 0.036"
      rpy="0 0 0" />
    <parent
      link="base_link" />
    <child
      link="rr_wheel_link" />
    <axis
      xyz="0 -1 0" />
  </joint>
</robot>